Workbook
Name TICKER: #REF!

Sheet Indicadores
A1: Indicadores | B1: Nome | C1: Fórmula
A2: DY | B2: Dividend Yield | C2: Dividendos (12 meses) / Preço da Ação
A3: LPA | B3: Lucro Por Ação | C3: Lucro Líquido / Qtde de Ações
A4: VPA | B4: Valor Patrimonial por Ação | C4: Patrimônio Líquido / Qtde de Ações
A5: CAGR | B5: Taxa de Cresc. Anual Composta | C5: (Valor Final / Valor Inicial)^(1 / Qtde Anos) - 1
A6: DPA | B6: Dividendo por Ação | C6: Payout / LPA
A7: PAYOUT | B7: Percentual Lucro Líquido Distribuído | C7: DPA / LPA

Sheet Ações
AF2: https://ceqef.fgv.br/bancos-de-dados
C3: MONITOR DE VALUATION DO MIRA
C11: IPCA | E11: 0.045
C12: ERP | E12: 0.0903
C13: PRêMIO DE RISCO | E13: 0.1353
B15: AÇÕES | C15: Nome Empresa | D15: Setor | E15: Segmento | F15: CÍCLICO | G15: PREÇO | H15: DY | I15: P/L | J15: LPA | K15: VPA | L15: DPA | M15: RISCO | N15: MARGEM DE DESCONTO | O15: PAYOUT | P15: CRESCIMNETO OU DIVIDENDOS | Q15: ROE | R15: CAGR LUCRO 5A | S15: CRESCIMENTO DAMODARAN | T15: MÉDIA DE CRESCIMENTO | U15: DESC. BAZIN | V15: PREÇO JUSTO BAZIN | W15: PREÇO TETO BAZIN | X15: DESC. GRAHAM | Y15: PREÇO JUSTO GRAHAM | Z15: PREÇO TETO GRAHAM | AA15: DESC. GORDON | AB15: D1 | AC15: PREÇO JUSTO GORDON | AD15: PREÇO TETO GORDON | AE15: ÍNDICE PEG
B16: ='Dados Status Invest'!A2 | C16: =VLOOKUP(Table_1[[#This Row],[AÇÕES]],'Classificação B3'!A:B,2,0) | D16: =VLOOKUP(Table_1[[#This Row],[AÇÕES]],'Classificação B3'!A:D,4,0) | E16: =VLOOKUP(Table_1[[#This Row],[AÇÕES]],'Classificação B3'!A:F,6,0) | F16: =VLOOKUP(Table_1[[#This Row],[AÇÕES]],'Classificação B3'!A:G,7,0) | G16: =VLOOKUP(Table_1[[#This Row],[AÇÕES]],'Dados Status Invest'!A:B,2,0) | H16: =VLOOKUP(Table_1[[#This Row],[AÇÕES]],'Dados Status Invest'!A:C,3,0)/100 | I16: =VLOOKUP(Table_1[[#This Row],[AÇÕES]],'Dados Status Invest'!A:D,4,0)/100 | J16: =VLOOKUP(Table_1[[#This Row],[AÇÕES]],'Dados Status Invest'!A:AB,28,0) | K16: =VLOOKUP(Table_1[[#This Row],[AÇÕES]],'Dados Status Invest'!A:AA,27,0) | L16: =Table_1[[#This Row],[PREÇO]]*Table_1[[#This Row],[DY]] | M16: =$E$13 | N16: 0.3 | O16: =Table_1[[#This Row],[DPA]]/Table_1[[#This Row],[LPA]] | P16: =IF(Table_1[[#This Row],[PAYOUT]]<=40%,"CRESCIMENTO",IF(Table_1[[#This Row],[PAYOUT]]<=60%,"INDEFINIDO","DIVIDENDOS")) | Q16: =VLOOKUP(Table_1[[#This Row],[AÇÕES]],'Dados Status Invest'!A:R,18,0)/100 | R16: =VLOOKUP(Table_1[[#This Row],[AÇÕES]],'Dados Status Invest'!A:Y,25,0)/100 | S16: =(1-Table_1[[#This Row],[PAYOUT]])*Table_1[[#This Row],[ROE]] | T16: =AVERAGE(Table_1[[#This Row],[CAGR LUCRO 5A]],Table_1[[#This Row],[CRESCIMENTO DAMODARAN]]) | U16: =(Table_1[[#This Row],[PREÇO JUSTO BAZIN]]-Table_1[[#This Row],[PREÇO]])/Table_1[[#This Row],[PREÇO JUSTO BAZIN]] | V16: =Table_1[[#This Row],[DPA]]/6% | W16: =Table_1[[#This Row],[PREÇO JUSTO BAZIN]]/(1+Table_1[[#This Row],[MARGEM DE DESCONTO]]) | X16: =(Table_1[[#This Row],[PREÇO JUSTO GRAHAM]]-Table_1[[#This Row],[PREÇO]])/Table_1[[#This Row],[PREÇO JUSTO GRAHAM]] | Y16: =(22.5*Table_1[[#This Row],[LPA]]*Table_1[[#This Row],[VPA]])^0.5 | Z16: =Table_1[[#This Row],[PREÇO JUSTO GRAHAM]]/(1+Table_1[[#This Row],[MARGEM DE DESCONTO]]) | AA16: =(Table_1[[#This Row],[PREÇO JUSTO GORDON]]-Table_1[[#This Row],[PREÇO]])/Table_1[[#This Row],[PREÇO JUSTO GORDON]] | AB16: =Table_1[[#This Row],[DPA]]*(1+Table_1[[#This Row],[MÉDIA DE CRESCIMENTO]]) | AC16: =Table_1[[#This Row],[D1]]/(Table_1[[#This Row],[RISCO]]-Table_1[[#This Row],[MÉDIA DE CRESCIMENTO]]) | AD16: =Table_1[[#This Row],[PREÇO JUSTO GORDON]]/(1+Table_1[[#This Row],[MARGEM DE DESCONTO]]) | AE16: =Table_1[[#This Row],[P/L]]/Table_1[[#This Row],[MÉDIA DE CRESCIMENTO]] | AG16: REGRA DE COLORAÇÃO | AH16: BAZIN | AI16: GRAHAM | AJ16: GORDON | AK16: PEG
B17: ='Dados Status Invest'!A3 | C17: =VLOOKUP(Table_1[[#This Row],[AÇÕES]],'Classificação B3'!A:B,2,0) | D17: =VLOOKUP(Table_1[[#This Row],[AÇÕES]],'Classificação B3'!A:D,4,0) | E17: =VLOOKUP(Table_1[[#This Row],[AÇÕES]],'Classificação B3'!A:F,6,0) | F17: =VLOOKUP(Table_1[[#This Row],[AÇÕES]],'Classificação B3'!A:G,7,0) | G17: =VLOOKUP(Table_1[[#This Row],[AÇÕES]],'Dados Status Invest'!A:B,2,0) | H17: =VLOOKUP(Table_1[[#This Row],[AÇÕES]],'Dados Status Invest'!A:C,3,0)/100 | I17: =VLOOKUP(Table_1[[#This Row],[AÇÕES]],'Dados Status Invest'!A:D,4,0)/100 | J17: =VLOOKUP(Table_1[[#This Row],[AÇÕES]],'Dados Status Invest'!A:AB,28,0) | K17: =VLOOKUP(Table_1[[#This Row],[AÇÕES]],'Dados Status Invest'!A:AA,27,0) | L17: =Table_1[[#This Row],[PREÇO]]*Table_1[[#This Row],[DY]] | M17: =$E$13 | N17: 0.3 | O17: =Table_1[[#This Row],[DPA]]/Table_1[[#This Row],[LPA]] | P17: =IF(Table_1[[#This Row],[PAYOUT]]<=40%,"CRESCIMENTO",IF(Table_1[[#This Row],[PAYOUT]]<=60%,"INDEFINIDO","DIVIDENDOS")) | Q17: =VLOOKUP(Table_1[[#This Row],[AÇÕES]],'Dados Status Invest'!A:R,18,0)/100 | R17: =VLOOKUP(Table_1[[#This Row],[AÇÕES]],'Dados Status Invest'!A:Y,25,0)/100 | S17: =(1-Table_1[[#This Row],[PAYOUT]])*Table_1[[#This Row],[ROE]] | T17: =AVERAGE(Table_1[[#This Row],[CAGR LUCRO 5A]],Table_1[[#This Row],[CRESCIMENTO DAMODARAN]]) | U17: =(Table_1[[#This Row],[PREÇO JUSTO BAZIN]]-Table_1[[#This Row],[PREÇO]])/Table_1[[#This Row],[PREÇO JUSTO BAZIN]] | V17: =Table_1[[#This Row],[DPA]]/6% | W17: =Table_1[[#This Row],[PREÇO JUSTO BAZIN]]/(1+Table_1[[#This Row],[MARGEM DE DESCONTO]]) | X17: =(Table_1[[#This Row],[PREÇO JUSTO GRAHAM]]-Table_1[[#This Row],[PREÇO]])/Table_1[[#This Row],[PREÇO JUSTO GRAHAM]] | Y17: =(22.5*Table_1[[#This Row],[LPA]]*Table_1[[#This Row],[VPA]])^0.5 | Z17: =Table_1[[#This Row],[PREÇO JUSTO GRAHAM]]/(1+Table_1[[#This Row],[MARGEM DE DESCONTO]]) | AA17: =(Table_1[[#This Row],[PREÇO JUSTO GORDON]]-Table_1[[#This Row],[PREÇO]])/Table_1[[#This Row],[PREÇO JUSTO GORDON]] | AB17: =Table_1[[#This Row],[DPA]]*(1+Table_1[[#This Row],[MÉDIA DE CRESCIMENTO]]) | AC17: =Table_1[[#This Row],[D1]]/(Table_1[[#This Row],[RISCO]]-Table_1[[#This Row],[MÉDIA DE CRESCIMENTO]]) | AD17: =Table_1[[#This Row],[PREÇO JUSTO GORDON]]/(1+Table_1[[#This Row],[MARGEM DE DESCONTO]]) | AE17: =Table_1[[#This Row],[P/L]]/Table_1[[#This Row],[MÉDIA DE CRESCIMENTO]] | AH17: ACIMA DE 30% | AI17: ACIMA DE 30% | AJ17: ACIMA DE 30% | AK17: ENTRE 0 E 0,5
B18: ='Dados Status Invest'!A4 | C18: =VLOOKUP(Table_1[[#This Row],[AÇÕES]],'Classificação B3'!A:B,2,0) | D18: =VLOOKUP(Table_1[[#This Row],[AÇÕES]],'Classificação B3'!A:D,4,0) | E18: =VLOOKUP(Table_1[[#This Row],[AÇÕES]],'Classificação B3'!A:F,6,0) | F18: =VLOOKUP(Table_1[[#This Row],[AÇÕES]],'Classificação B3'!A:G,7,0) | G18: =VLOOKUP(Table_1[[#This Row],[AÇÕES]],'Dados Status Invest'!A:B,2,0) | H18: =VLOOKUP(Table_1[[#This Row],[AÇÕES]],'Dados Status Invest'!A:C,3,0)/100 | I18: =VLOOKUP(Table_1[[#This Row],[AÇÕES]],'Dados Status Invest'!A:D,4,0)/100 | J18: =VLOOKUP(Table_1[[#This Row],[AÇÕES]],'Dados Status Invest'!A:AB,28,0) | K18: =VLOOKUP(Table_1[[#This Row],[AÇÕES]],'Dados Status Invest'!A:AA,27,0) | L18: =Table_1[[#This Row],[PREÇO]]*Table_1[[#This Row],[DY]] | M18: =$E$13 | N18: 0.3 | O18: =Table_1[[#This Row],[DPA]]/Table_1[[#This Row],[LPA]] | P18: =IF(Table_1[[#This Row],[PAYOUT]]<=40%,"CRESCIMENTO",IF(Table_1[[#This Row],[PAYOUT]]<=60%,"INDEFINIDO","DIVIDENDOS")) | Q18: =VLOOKUP(Table_1[[#This Row],[AÇÕES]],'Dados Status Invest'!A:R,18,0)/100 | R18: =VLOOKUP(Table_1[[#This Row],[AÇÕES]],'Dados Status Invest'!A:Y,25,0)/100 | S18: =(1-Table_1[[#This Row],[PAYOUT]])*Table_1[[#This Row],[ROE]] | T18: =AVERAGE(Table_1[[#This Row],[CAGR LUCRO 5A]],Table_1[[#This Row],[CRESCIMENTO DAMODARAN]]) | U18: =(Table_1[[#This Row],[PREÇO JUSTO BAZIN]]-Table_1[[#This Row],[PREÇO]])/Table_1[[#This Row],[PREÇO JUSTO BAZIN]] | V18: =Table_1[[#This Row],[DPA]]/6% | W18: =Table_1[[#This Row],[PREÇO JUSTO BAZIN]]/(1+Table_1[[#This Row],[MARGEM DE DESCONTO]]) | X18: =(Table_1[[#This Row],[PREÇO JUSTO GRAHAM]]-Table_1[[#This Row],[PREÇO]])/Table_1[[#This Row],[PREÇO JUSTO GRAHAM]] | Y18: =(22.5*Table_1[[#This Row],[LPA]]*Table_1[[#This Row],[VPA]])^0.5 | Z18: =Table_1[[#This Row],[PREÇO JUSTO GRAHAM]]/(1+Table_1[[#This Row],[MARGEM DE DESCONTO]]) | AA18: =(Table_1[[#This Row],[PREÇO JUSTO GORDON]]-Table_1[[#This Row],[PREÇO]])/Table_1[[#This Row],[PREÇO JUSTO GORDON]] | AB18: =Table_1[[#This Row],[DPA]]*(1+Table_1[[#This Row],[MÉDIA DE CRESCIMENTO]]) | AC18: =Table_1[[#This Row],[D1]]/(Table_1[[#This Row],[RISCO]]-Table_1[[#This Row],[MÉDIA DE CRESCIMENTO]]) | AD18: =Table_1[[#This Row],[PREÇO JUSTO GORDON]]/(1+Table_1[[#This Row],[MARGEM DE DESCONTO]]) | AE18: =Table_1[[#This Row],[P/L]]/Table_1[[#This Row],[MÉDIA DE CRESCIMENTO]]
B19: ='Dados Status Invest'!A5 | C19: =VLOOKUP(Table_1[[#This Row],[AÇÕES]],'Classificação B3'!A:B,2,0) | D19: =VLOOKUP(Table_1[[#This Row],[AÇÕES]],'Classificação B3'!A:D,4,0) | E19: =VLOOKUP(Table_1[[#This Row],[AÇÕES]],'Classificação B3'!A:F,6,0) | F19: =VLOOKUP(Table_1[[#This Row],[AÇÕES]],'Classificação B3'!A:G,7,0) | G19: =VLOOKUP(Table_1[[#This Row],[AÇÕES]],'Dados Status Invest'!A:B,2,0) | H19: =VLOOKUP(Table_1[[#This Row],[AÇÕES]],'Dados Status Invest'!A:C,3,0)/100 | I19: =VLOOKUP(Table_1[[#This Row],[AÇÕES]],'Dados Status Invest'!A:D,4,0)/100 | J19: =VLOOKUP(Table_1[[#This Row],[AÇÕES]],'Dados Status Invest'!A:AB,28,0) | K19: =VLOOKUP(Table_1[[#This Row],[AÇÕES]],'Dados Status Invest'!A:AA,27,0) | L19: =Table_1[[#This Row],[PREÇO]]*Table_1[[#This Row],[DY]] | M19: =$E$13 | N19: 0.3 | O19: =Table_1[[#This Row],[DPA]]/Table_1[[#This Row],[LPA]] | P19: =IF(Table_1[[#This Row],[PAYOUT]]<=40%,"CRESCIMENTO",IF(Table_1[[#This Row],[PAYOUT]]<=60%,"INDEFINIDO","DIVIDENDOS")) | Q19: =VLOOKUP(Table_1[[#This Row],[AÇÕES]],'Dados Status Invest'!A:R,18,0)/100 | R19: =VLOOKUP(Table_1[[#This Row],[AÇÕES]],'Dados Status Invest'!A:Y,25,0)/100 | S19: =(1-Table_1[[#This Row],[PAYOUT]])*Table_1[[#This Row],[ROE]] | T19: =AVERAGE(Table_1[[#This Row],[CAGR LUCRO 5A]],Table_1[[#This Row],[CRESCIMENTO DAMODARAN]]) | U19: =(Table_1[[#This Row],[PREÇO JUSTO BAZIN]]-Table_1[[#This Row],[PREÇO]])/Table_1[[#This Row],[PREÇO JUSTO BAZIN]] | V19: =Table_1[[#This Row],[DPA]]/6% | W19: =Table_1[[#This Row],[PREÇO JUSTO BAZIN]]/(1+Table_1[[#This Row],[MARGEM DE DESCONTO]]) | X19: =(Table_1[[#This Row],[PREÇO JUSTO GRAHAM]]-Table_1[[#This Row],[PREÇO]])/Table_1[[#This Row],[PREÇO JUSTO GRAHAM]] | Y19: =(22.5*Table_1[[#This Row],[LPA]]*Table_1[[#This Row],[VPA]])^0.5 | Z19: =Table_1[[#This Row],[PREÇO JUSTO GRAHAM]]/(1+Table_1[[#This Row],[MARGEM DE DESCONTO]]) | AA19: =(Table_1[[#This Row],[PREÇO JUSTO GORDON]]-Table_1[[#This Row],[PREÇO]])/Table_1[[#This Row],[PREÇO JUSTO GORDON]] | AB19: =Table_1[[#This Row],[DPA]]*(1+Table_1[[#This Row],[MÉDIA DE CRESCIMENTO]]) | AC19: =Table_1[[#This Row],[D1]]/(Table_1[[#This Row],[RISCO]]-Table_1[[#This Row],[MÉDIA DE CRESCIMENTO]]) | AD19: =Table_1[[#This Row],[PREÇO JUSTO GORDON]]/(1+Table_1[[#This Row],[MARGEM DE DESCONTO]]) | AE19: =Table_1[[#This Row],[P/L]]/Table_1[[#This Row],[MÉDIA DE CRESCIMENTO]] | AH19: ENTRE 0 E 30% | AI19: ENTRE 0 E 30% | AJ19: ENTRE 0 E 30% | AK19: ENTRE 0,5 E 2
B20: ='Dados Status Invest'!A6 | C20: =VLOOKUP(Table_1[[#This Row],[AÇÕES]],'Classificação B3'!A:B,2,0) | D20: =VLOOKUP(Table_1[[#This Row],[AÇÕES]],'Classificação B3'!A:D,4,0) | E20: =VLOOKUP(Table_1[[#This Row],[AÇÕES]],'Classificação B3'!A:F,6,0) | F20: =VLOOKUP(Table_1[[#This Row],[AÇÕES]],'Classificação B3'!A:G,7,0) | G20: =VLOOKUP(Table_1[[#This Row],[AÇÕES]],'Dados Status Invest'!A:B,2,0) | H20: =VLOOKUP(Table_1[[#This Row],[AÇÕES]],'Dados Status Invest'!A:C,3,0)/100 | I20: =VLOOKUP(Table_1[[#This Row],[AÇÕES]],'Dados Status Invest'!A:D,4,0)/100 | J20: =VLOOKUP(Table_1[[#This Row],[AÇÕES]],'Dados Status Invest'!A:AB,28,0) | K20: =VLOOKUP(Table_1[[#This Row],[AÇÕES]],'Dados Status Invest'!A:AA,27,0) | L20: =Table_1[[#This Row],[PREÇO]]*Table_1[[#This Row],[DY]] | M20: =$E$13 | N20: 0.3 | O20: =Table_1[[#This Row],[DPA]]/Table_1[[#This Row],[LPA]] | P20: =IF(Table_1[[#This Row],[PAYOUT]]<=40%,"CRESCIMENTO",IF(Table_1[[#This Row],[PAYOUT]]<=60%,"INDEFINIDO","DIVIDENDOS")) | Q20: =VLOOKUP(Table_1[[#This Row],[AÇÕES]],'Dados Status Invest'!A:R,18,0)/100 | R20: =VLOOKUP(Table_1[[#This Row],[AÇÕES]],'Dados Status Invest'!A:Y,25,0)/100 | S20: =(1-Table_1[[#This Row],[PAYOUT]])*Table_1[[#This Row],[ROE]] | T20: =AVERAGE(Table_1[[#This Row],[CAGR LUCRO 5A]],Table_1[[#This Row],[CRESCIMENTO DAMODARAN]]) | U20: =(Table_1[[#This Row],[PREÇO JUSTO BAZIN]]-Table_1[[#This Row],[PREÇO]])/Table_1[[#This Row],[PREÇO JUSTO BAZIN]] | V20: =Table_1[[#This Row],[DPA]]/6% | W20: =Table_1[[#This Row],[PREÇO JUSTO BAZIN]]/(1+Table_1[[#This Row],[MARGEM DE DESCONTO]]) | X20: =(Table_1[[#This Row],[PREÇO JUSTO GRAHAM]]-Table_1[[#This Row],[PREÇO]])/Table_1[[#This Row],[PREÇO JUSTO GRAHAM]] | Y20: =(22.5*Table_1[[#This Row],[LPA]]*Table_1[[#This Row],[VPA]])^0.5 | Z20: =Table_1[[#This Row],[PREÇO JUSTO GRAHAM]]/(1+Table_1[[#This Row],[MARGEM DE DESCONTO]]) | AA20: =(Table_1[[#This Row],[PREÇO JUSTO GORDON]]-Table_1[[#This Row],[PREÇO]])/Table_1[[#This Row],[PREÇO JUSTO GORDON]] | AB20: =Table_1[[#This Row],[DPA]]*(1+Table_1[[#This Row],[MÉDIA DE CRESCIMENTO]]) | AC20: =Table_1[[#This Row],[D1]]/(Table_1[[#This Row],[RISCO]]-Table_1[[#This Row],[MÉDIA DE CRESCIMENTO]]) | AD20: =Table_1[[#This Row],[PREÇO JUSTO GORDON]]/(1+Table_1[[#This Row],[MARGEM DE DESCONTO]]) | AE20: =Table_1[[#This Row],[P/L]]/Table_1[[#This Row],[MÉDIA DE CRESCIMENTO]]
B21: ='Dados Status Invest'!A7 | C21: =VLOOKUP(Table_1[[#This Row],[AÇÕES]],'Classificação B3'!A:B,2,0) | D21: =VLOOKUP(Table_1[[#This Row],[AÇÕES]],'Classificação B3'!A:D,4,0) | E21: =VLOOKUP(Table_1[[#This Row],[AÇÕES]],'Classificação B3'!A:F,6,0) | F21: =VLOOKUP(Table_1[[#This Row],[AÇÕES]],'Classificação B3'!A:G,7,0) | G21: =VLOOKUP(Table_1[[#This Row],[AÇÕES]],'Dados Status Invest'!A:B,2,0) | H21: =VLOOKUP(Table_1[[#This Row],[AÇÕES]],'Dados Status Invest'!A:C,3,0)/100 | I21: =VLOOKUP(Table_1[[#This Row],[AÇÕES]],'Dados Status Invest'!A:D,4,0)/100 | J21: =VLOOKUP(Table_1[[#This Row],[AÇÕES]],'Dados Status Invest'!A:AB,28,0) | K21: =VLOOKUP(Table_1[[#This Row],[AÇÕES]],'Dados Status Invest'!A:AA,27,0) | L21: =Table_1[[#This Row],[PREÇO]]*Table_1[[#This Row],[DY]] | M21: =$E$13 | N21: 0.3 | O21: =Table_1[[#This Row],[DPA]]/Table_1[[#This Row],[LPA]] | P21: =IF(Table_1[[#This Row],[PAYOUT]]<=40%,"CRESCIMENTO",IF(Table_1[[#This Row],[PAYOUT]]<=60%,"INDEFINIDO","DIVIDENDOS")) | Q21: =VLOOKUP(Table_1[[#This Row],[AÇÕES]],'Dados Status Invest'!A:R,18,0)/100 | R21: =VLOOKUP(Table_1[[#This Row],[AÇÕES]],'Dados Status Invest'!A:Y,25,0)/100 | S21: =(1-Table_1[[#This Row],[PAYOUT]])*Table_1[[#This Row],[ROE]] | T21: =AVERAGE(Table_1[[#This Row],[CAGR LUCRO 5A]],Table_1[[#This Row],[CRESCIMENTO DAMODARAN]]) | U21: =(Table_1[[#This Row],[PREÇO JUSTO BAZIN]]-Table_1[[#This Row],[PREÇO]])/Table_1[[#This Row],[PREÇO JUSTO BAZIN]] | V21: =Table_1[[#This Row],[DPA]]/6% | W21: =Table_1[[#This Row],[PREÇO JUSTO BAZIN]]/(1+Table_1[[#This Row],[MARGEM DE DESCONTO]]) | X21: =(Table_1[[#This Row],[PREÇO JUSTO GRAHAM]]-Table_1[[#This Row],[PREÇO]])/Table_1[[#This Row],[PREÇO JUSTO GRAHAM]] | Y21: =(22.5*Table_1[[#This Row],[LPA]]*Table_1[[#This Row],[VPA]])^0.5 | Z21: =Table_1[[#This Row],[PREÇO JUSTO GRAHAM]]/(1+Table_1[[#This Row],[MARGEM DE DESCONTO]]) | AA21: =(Table_1[[#This Row],[PREÇO JUSTO GORDON]]-Table_1[[#This Row],[PREÇO]])/Table_1[[#This Row],[PREÇO JUSTO GORDON]] | AB21: =Table_1[[#This Row],[DPA]]*(1+Table_1[[#This Row],[MÉDIA DE CRESCIMENTO]]) | AC21: =Table_1[[#This Row],[D1]]/(Table_1[[#This Row],[RISCO]]-Table_1[[#This Row],[MÉDIA DE CRESCIMENTO]]) | AD21: =Table_1[[#This Row],[PREÇO JUSTO GORDON]]/(1+Table_1[[#This Row],[MARGEM DE DESCONTO]]) | AE21: =Table_1[[#This Row],[P/L]]/Table_1[[#This Row],[MÉDIA DE CRESCIMENTO]]
B22: ='Dados Status Invest'!A8 | C22: =VLOOKUP(Table_1[[#This Row],[AÇÕES]],'Classificação B3'!A:B,2,0) | D22: =VLOOKUP(Table_1[[#This Row],[AÇÕES]],'Classificação B3'!A:D,4,0) | E22: =VLOOKUP(Table_1[[#This Row],[AÇÕES]],'Classificação B3'!A:F,6,0) | F22: =VLOOKUP(Table_1[[#This Row],[AÇÕES]],'Classificação B3'!A:G,7,0) | G22: =VLOOKUP(Table_1[[#This Row],[AÇÕES]],'Dados Status Invest'!A:B,2,0) | H22: =VLOOKUP(Table_1[[#This Row],[AÇÕES]],'Dados Status Invest'!A:C,3,0)/100 | I22: =VLOOKUP(Table_1[[#This Row],[AÇÕES]],'Dados Status Invest'!A:D,4,0)/100 | J22: =VLOOKUP(Table_1[[#This Row],[AÇÕES]],'Dados Status Invest'!A:AB,28,0) | K22: =VLOOKUP(Table_1[[#This Row],[AÇÕES]],'Dados Status Invest'!A:AA,27,0) | L22: =Table_1[[#This Row],[PREÇO]]*Table_1[[#This Row],[DY]] | M22: =$E$13 | N22: 0.3 | O22: =Table_1[[#This Row],[DPA]]/Table_1[[#This Row],[LPA]] | P22: =IF(Table_1[[#This Row],[PAYOUT]]<=40%,"CRESCIMENTO",IF(Table_1[[#This Row],[PAYOUT]]<=60%,"INDEFINIDO","DIVIDENDOS")) | Q22: =VLOOKUP(Table_1[[#This Row],[AÇÕES]],'Dados Status Invest'!A:R,18,0)/100 | R22: =VLOOKUP(Table_1[[#This Row],[AÇÕES]],'Dados Status Invest'!A:Y,25,0)/100 | S22: =(1-Table_1[[#This Row],[PAYOUT]])*Table_1[[#This Row],[ROE]] | T22: =AVERAGE(Table_1[[#This Row],[CAGR LUCRO 5A]],Table_1[[#This Row],[CRESCIMENTO DAMODARAN]]) | U22: =(Table_1[[#This Row],[PREÇO JUSTO BAZIN]]-Table_1[[#This Row],[PREÇO]])/Table_1[[#This Row],[PREÇO JUSTO BAZIN]] | V22: =Table_1[[#This Row],[DPA]]/6% | W22: =Table_1[[#This Row],[PREÇO JUSTO BAZIN]]/(1+Table_1[[#This Row],[MARGEM DE DESCONTO]]) | X22: =(Table_1[[#This Row],[PREÇO JUSTO GRAHAM]]-Table_1[[#This Row],[PREÇO]])/Table_1[[#This Row],[PREÇO JUSTO GRAHAM]] | Y22: =(22.5*Table_1[[#This Row],[LPA]]*Table_1[[#This Row],[VPA]])^0.5 | Z22: =Table_1[[#This Row],[PREÇO JUSTO GRAHAM]]/(1+Table_1[[#This Row],[MARGEM DE DESCONTO]]) | AA22: =(Table_1[[#This Row],[PREÇO JUSTO GORDON]]-Table_1[[#This Row],[PREÇO]])/Table_1[[#This Row],[PREÇO JUSTO GORDON]] | AB22: =Table_1[[#This Row],[DPA]]*(1+Table_1[[#This Row],[MÉDIA DE CRESCIMENTO]]) | AC22: =Table_1[[#This Row],[D1]]/(Table_1[[#This Row],[RISCO]]-Table_1[[#This Row],[MÉDIA DE CRESCIMENTO]]) | AD22: =Table_1[[#This Row],[PREÇO JUSTO GORDON]]/(1+Table_1[[#This Row],[MARGEM DE DESCONTO]]) | AE22: =Table_1[[#This Row],[P/L]]/Table_1[[#This Row],[MÉDIA DE CRESCIMENTO]] | AH22: ABAIXO DE ZERO | AI22: ABAIXO DE ZERO | AJ22: ABAIXO DE ZERO | AK22: ABAIXO DE 0 OU ACIMA DE 2
B23: ='Dados Status Invest'!A9 | C23: =VLOOKUP(Table_1[[#This Row],[AÇÕES]],'Classificação B3'!A:B,2,0) | D23: =VLOOKUP(Table_1[[#This Row],[AÇÕES]],'Classificação B3'!A:D,4,0) | E23: =VLOOKUP(Table_1[[#This Row],[AÇÕES]],'Classificação B3'!A:F,6,0) | F23: =VLOOKUP(Table_1[[#This Row],[AÇÕES]],'Classificação B3'!A:G,7,0) | G23: =VLOOKUP(Table_1[[#This Row],[AÇÕES]],'Dados Status Invest'!A:B,2,0) | H23: =VLOOKUP(Table_1[[#This Row],[AÇÕES]],'Dados Status Invest'!A:C,3,0)/100 | I23: =VLOOKUP(Table_1[[#This Row],[AÇÕES]],'Dados Status Invest'!A:D,4,0)/100 | J23: =VLOOKUP(Table_1[[#This Row],[AÇÕES]],'Dados Status Invest'!A:AB,28,0) | K23: =VLOOKUP(Table_1[[#This Row],[AÇÕES]],'Dados Status Invest'!A:AA,27,0) | L23: =Table_1[[#This Row],[PREÇO]]*Table_1[[#This Row],[DY]] | M23: =$E$13 | N23: 0.3 | O23: =Table_1[[#This Row],[DPA]]/Table_1[[#This Row],[LPA]] | P23: =IF(Table_1[[#This Row],[PAYOUT]]<=40%,"CRESCIMENTO",IF(Table_1[[#This Row],[PAYOUT]]<=60%,"INDEFINIDO","DIVIDENDOS")) | Q23: =VLOOKUP(Table_1[[#This Row],[AÇÕES]],'Dados Status Invest'!A:R,18,0)/100 | R23: =VLOOKUP(Table_1[[#This Row],[AÇÕES]],'Dados Status Invest'!A:Y,25,0)/100 | S23: =(1-Table_1[[#This Row],[PAYOUT]])*Table_1[[#This Row],[ROE]] | T23: =AVERAGE(Table_1[[#This Row],[CAGR LUCRO 5A]],Table_1[[#This Row],[CRESCIMENTO DAMODARAN]]) | U23: =(Table_1[[#This Row],[PREÇO JUSTO BAZIN]]-Table_1[[#This Row],[PREÇO]])/Table_1[[#This Row],[PREÇO JUSTO BAZIN]] | V23: =Table_1[[#This Row],[DPA]]/6% | W23: =Table_1[[#This Row],[PREÇO JUSTO BAZIN]]/(1+Table_1[[#This Row],[MARGEM DE DESCONTO]]) | X23: =(Table_1[[#This Row],[PREÇO JUSTO GRAHAM]]-Table_1[[#This Row],[PREÇO]])/Table_1[[#This Row],[PREÇO JUSTO GRAHAM]] | Y23: =(22.5*Table_1[[#This Row],[LPA]]*Table_1[[#This Row],[VPA]])^0.5 | Z23: =Table_1[[#This Row],[PREÇO JUSTO GRAHAM]]/(1+Table_1[[#This Row],[MARGEM DE DESCONTO]]) | AA23: =(Table_1[[#This Row],[PREÇO JUSTO GORDON]]-Table_1[[#This Row],[PREÇO]])/Table_1[[#This Row],[PREÇO JUSTO GORDON]] | AB23: =Table_1[[#This Row],[DPA]]*(1+Table_1[[#This Row],[MÉDIA DE CRESCIMENTO]]) | AC23: =Table_1[[#This Row],[D1]]/(Table_1[[#This Row],[RISCO]]-Table_1[[#This Row],[MÉDIA DE CRESCIMENTO]]) | AD23: =Table_1[[#This Row],[PREÇO JUSTO GORDON]]/(1+Table_1[[#This Row],[MARGEM DE DESCONTO]]) | AE23: =Table_1[[#This Row],[P/L]]/Table_1[[#This Row],[MÉDIA DE CRESCIMENTO]]
B24: ='Dados Status Invest'!A10 | C24: =VLOOKUP(Table_1[[#This Row],[AÇÕES]],'Classificação B3'!A:B,2,0) | D24: =VLOOKUP(Table_1[[#This Row],[AÇÕES]],'Classificação B3'!A:D,4,0) | E24: =VLOOKUP(Table_1[[#This Row],[AÇÕES]],'Classificação B3'!A:F,6,0) | F24: =VLOOKUP(Table_1[[#This Row],[AÇÕES]],'Classificação B3'!A:G,7,0) | G24: =VLOOKUP(Table_1[[#This Row],[AÇÕES]],'Dados Status Invest'!A:B,2,0) | H24: =VLOOKUP(Table_1[[#This Row],[AÇÕES]],'Dados Status Invest'!A:C,3,0)/100 | I24: =VLOOKUP(Table_1[[#This Row],[AÇÕES]],'Dados Status Invest'!A:D,4,0)/100 | J24: =VLOOKUP(Table_1[[#This Row],[AÇÕES]],'Dados Status Invest'!A:AB,28,0) | K24: =VLOOKUP(Table_1[[#This Row],[AÇÕES]],'Dados Status Invest'!A:AA,27,0) | L24: =Table_1[[#This Row],[PREÇO]]*Table_1[[#This Row],[DY]] | M24: =$E$13 | N24: 0.3 | O24: =Table_1[[#This Row],[DPA]]/Table_1[[#This Row],[LPA]] | P24: =IF(Table_1[[#This Row],[PAYOUT]]<=40%,"CRESCIMENTO",IF(Table_1[[#This Row],[PAYOUT]]<=60%,"INDEFINIDO","DIVIDENDOS")) | Q24: =VLOOKUP(Table_1[[#This Row],[AÇÕES]],'Dados Status Invest'!A:R,18,0)/100 | R24: =VLOOKUP(Table_1[[#This Row],[AÇÕES]],'Dados Status Invest'!A:Y,25,0)/100 | S24: =(1-Table_1[[#This Row],[PAYOUT]])*Table_1[[#This Row],[ROE]] | T24: =AVERAGE(Table_1[[#This Row],[CAGR LUCRO 5A]],Table_1[[#This Row],[CRESCIMENTO DAMODARAN]]) | U24: =(Table_1[[#This Row],[PREÇO JUSTO BAZIN]]-Table_1[[#This Row],[PREÇO]])/Table_1[[#This Row],[PREÇO JUSTO BAZIN]] | V24: =Table_1[[#This Row],[DPA]]/6% | W24: =Table_1[[#This Row],[PREÇO JUSTO BAZIN]]/(1+Table_1[[#This Row],[MARGEM DE DESCONTO]]) | X24: =(Table_1[[#This Row],[PREÇO JUSTO GRAHAM]]-Table_1[[#This Row],[PREÇO]])/Table_1[[#This Row],[PREÇO JUSTO GRAHAM]] | Y24: =(22.5*Table_1[[#This Row],[LPA]]*Table_1[[#This Row],[VPA]])^0.5 | Z24: =Table_1[[#This Row],[PREÇO JUSTO GRAHAM]]/(1+Table_1[[#This Row],[MARGEM DE DESCONTO]]) | AA24: =(Table_1[[#This Row],[PREÇO JUSTO GORDON]]-Table_1[[#This Row],[PREÇO]])/Table_1[[#This Row],[PREÇO JUSTO GORDON]] | AB24: =Table_1[[#This Row],[DPA]]*(1+Table_1[[#This Row],[MÉDIA DE CRESCIMENTO]]) | AC24: =Table_1[[#This Row],[D1]]/(Table_1[[#This Row],[RISCO]]-Table_1[[#This Row],[MÉDIA DE CRESCIMENTO]]) | AD24: =Table_1[[#This Row],[PREÇO JUSTO GORDON]]/(1+Table_1[[#This Row],[MARGEM DE DESCONTO]]) | AE24: =Table_1[[#This Row],[P/L]]/Table_1[[#This Row],[MÉDIA DE CRESCIMENTO]]
B25: ='Dados Status Invest'!A11 | C25: =VLOOKUP(Table_1[[#This Row],[AÇÕES]],'Classificação B3'!A:B,2,0) | D25: =VLOOKUP(Table_1[[#This Row],[AÇÕES]],'Classificação B3'!A:D,4,0) | E25: =VLOOKUP(Table_1[[#This Row],[AÇÕES]],'Classificação B3'!A:F,6,0) | F25: =VLOOKUP(Table_1[[#This Row],[AÇÕES]],'Classificação B3'!A:G,7,0) | G25: =VLOOKUP(Table_1[[#This Row],[AÇÕES]],'Dados Status Invest'!A:B,2,0) | H25: =VLOOKUP(Table_1[[#This Row],[AÇÕES]],'Dados Status Invest'!A:C,3,0)/100 | I25: =VLOOKUP(Table_1[[#This Row],[AÇÕES]],'Dados Status Invest'!A:D,4,0)/100 | J25: =VLOOKUP(Table_1[[#This Row],[AÇÕES]],'Dados Status Invest'!A:AB,28,0) | K25: =VLOOKUP(Table_1[[#This Row],[AÇÕES]],'Dados Status Invest'!A:AA,27,0) | L25: =Table_1[[#This Row],[PREÇO]]*Table_1[[#This Row],[DY]] | M25: =$E$13 | N25: 0.3 | O25: =Table_1[[#This Row],[DPA]]/Table_1[[#This Row],[LPA]] | P25: =IF(Table_1[[#This Row],[PAYOUT]]<=40%,"CRESCIMENTO",IF(Table_1[[#This Row],[PAYOUT]]<=60%,"INDEFINIDO","DIVIDENDOS")) | Q25: =VLOOKUP(Table_1[[#This Row],[AÇÕES]],'Dados Status Invest'!A:R,18,0)/100 | R25: =VLOOKUP(Table_1[[#This Row],[AÇÕES]],'Dados Status Invest'!A:Y,25,0)/100 | S25: =(1-Table_1[[#This Row],[PAYOUT]])*Table_1[[#This Row],[ROE]] | T25: =AVERAGE(Table_1[[#This Row],[CAGR LUCRO 5A]],Table_1[[#This Row],[CRESCIMENTO DAMODARAN]]) | U25: =(Table_1[[#This Row],[PREÇO JUSTO BAZIN]]-Table_1[[#This Row],[PREÇO]])/Table_1[[#This Row],[PREÇO JUSTO BAZIN]] | V25: =Table_1[[#This Row],[DPA]]/6% | W25: =Table_1[[#This Row],[PREÇO JUSTO BAZIN]]/(1+Table_1[[#This Row],[MARGEM DE DESCONTO]]) | X25: =(Table_1[[#This Row],[PREÇO JUSTO GRAHAM]]-Table_1[[#This Row],[PREÇO]])/Table_1[[#This Row],[PREÇO JUSTO GRAHAM]] | Y25: =(22.5*Table_1[[#This Row],[LPA]]*Table_1[[#This Row],[VPA]])^0.5 | Z25: =Table_1[[#This Row],[PREÇO JUSTO GRAHAM]]/(1+Table_1[[#This Row],[MARGEM DE DESCONTO]]) | AA25: =(Table_1[[#This Row],[PREÇO JUSTO GORDON]]-Table_1[[#This Row],[PREÇO]])/Table_1[[#This Row],[PREÇO JUSTO GORDON]] | AB25: =Table_1[[#This Row],[DPA]]*(1+Table_1[[#This Row],[MÉDIA DE CRESCIMENTO]]) | AC25: =Table_1[[#This Row],[D1]]/(Table_1[[#This Row],[RISCO]]-Table_1[[#This Row],[MÉDIA DE CRESCIMENTO]]) | AD25: =Table_1[[#This Row],[PREÇO JUSTO GORDON]]/(1+Table_1[[#This Row],[MARGEM DE DESCONTO]]) | AE25: =Table_1[[#This Row],[P/L]]/Table_1[[#This Row],[MÉDIA DE CRESCIMENTO]] | AG25: MÉDIA CRESCIMENTO
B26: ='Dados Status Invest'!A12 | C26: =VLOOKUP(Table_1[[#This Row],[AÇÕES]],'Classificação B3'!A:B,2,0) | D26: =VLOOKUP(Table_1[[#This Row],[AÇÕES]],'Classificação B3'!A:D,4,0) | E26: =VLOOKUP(Table_1[[#This Row],[AÇÕES]],'Classificação B3'!A:F,6,0) | F26: =VLOOKUP(Table_1[[#This Row],[AÇÕES]],'Classificação B3'!A:G,7,0) | G26: =VLOOKUP(Table_1[[#This Row],[AÇÕES]],'Dados Status Invest'!A:B,2,0) | H26: =VLOOKUP(Table_1[[#This Row],[AÇÕES]],'Dados Status Invest'!A:C,3,0)/100 | I26: =VLOOKUP(Table_1[[#This Row],[AÇÕES]],'Dados Status Invest'!A:D,4,0)/100 | J26: =VLOOKUP(Table_1[[#This Row],[AÇÕES]],'Dados Status Invest'!A:AB,28,0) | K26: =VLOOKUP(Table_1[[#This Row],[AÇÕES]],'Dados Status Invest'!A:AA,27,0) | L26: =Table_1[[#This Row],[PREÇO]]*Table_1[[#This Row],[DY]] | M26: =$E$13 | N26: 0.3 | O26: =Table_1[[#This Row],[DPA]]/Table_1[[#This Row],[LPA]] | P26: =IF(Table_1[[#This Row],[PAYOUT]]<=40%,"CRESCIMENTO",IF(Table_1[[#This Row],[PAYOUT]]<=60%,"INDEFINIDO","DIVIDENDOS")) | Q26: =VLOOKUP(Table_1[[#This Row],[AÇÕES]],'Dados Status Invest'!A:R,18,0)/100 | R26: =VLOOKUP(Table_1[[#This Row],[AÇÕES]],'Dados Status Invest'!A:Y,25,0)/100 | S26: =(1-Table_1[[#This Row],[PAYOUT]])*Table_1[[#This Row],[ROE]] | T26: =AVERAGE(Table_1[[#This Row],[CAGR LUCRO 5A]],Table_1[[#This Row],[CRESCIMENTO DAMODARAN]]) | U26: =(Table_1[[#This Row],[PREÇO JUSTO BAZIN]]-Table_1[[#This Row],[PREÇO]])/Table_1[[#This Row],[PREÇO JUSTO BAZIN]] | V26: =Table_1[[#This Row],[DPA]]/6% | W26: =Table_1[[#This Row],[PREÇO JUSTO BAZIN]]/(1+Table_1[[#This Row],[MARGEM DE DESCONTO]]) | X26: =(Table_1[[#This Row],[PREÇO JUSTO GRAHAM]]-Table_1[[#This Row],[PREÇO]])/Table_1[[#This Row],[PREÇO JUSTO GRAHAM]] | Y26: =(22.5*Table_1[[#This Row],[LPA]]*Table_1[[#This Row],[VPA]])^0.5 | Z26: =Table_1[[#This Row],[PREÇO JUSTO GRAHAM]]/(1+Table_1[[#This Row],[MARGEM DE DESCONTO]]) | AA26: =(Table_1[[#This Row],[PREÇO JUSTO GORDON]]-Table_1[[#This Row],[PREÇO]])/Table_1[[#This Row],[PREÇO JUSTO GORDON]] | AB26: =Table_1[[#This Row],[DPA]]*(1+Table_1[[#This Row],[MÉDIA DE CRESCIMENTO]]) | AC26: =Table_1[[#This Row],[D1]]/(Table_1[[#This Row],[RISCO]]-Table_1[[#This Row],[MÉDIA DE CRESCIMENTO]]) | AD26: =Table_1[[#This Row],[PREÇO JUSTO GORDON]]/(1+Table_1[[#This Row],[MARGEM DE DESCONTO]]) | AE26: =Table_1[[#This Row],[P/L]]/Table_1[[#This Row],[MÉDIA DE CRESCIMENTO]] | AH26: Abaixo de Zero
B27: ='Dados Status Invest'!A13 | C27: =VLOOKUP(Table_1[[#This Row],[AÇÕES]],'Classificação B3'!A:B,2,0) | D27: =VLOOKUP(Table_1[[#This Row],[AÇÕES]],'Classificação B3'!A:D,4,0) | E27: =VLOOKUP(Table_1[[#This Row],[AÇÕES]],'Classificação B3'!A:F,6,0) | F27: =VLOOKUP(Table_1[[#This Row],[AÇÕES]],'Classificação B3'!A:G,7,0) | G27: =VLOOKUP(Table_1[[#This Row],[AÇÕES]],'Dados Status Invest'!A:B,2,0) | H27: =VLOOKUP(Table_1[[#This Row],[AÇÕES]],'Dados Status Invest'!A:C,3,0)/100 | I27: =VLOOKUP(Table_1[[#This Row],[AÇÕES]],'Dados Status Invest'!A:D,4,0)/100 | J27: =VLOOKUP(Table_1[[#This Row],[AÇÕES]],'Dados Status Invest'!A:AB,28,0) | K27: =VLOOKUP(Table_1[[#This Row],[AÇÕES]],'Dados Status Invest'!A:AA,27,0) | L27: =Table_1[[#This Row],[PREÇO]]*Table_1[[#This Row],[DY]] | M27: =$E$13 | N27: 0.3 | O27: =Table_1[[#This Row],[DPA]]/Table_1[[#This Row],[LPA]] | P27: =IF(Table_1[[#This Row],[PAYOUT]]<=40%,"CRESCIMENTO",IF(Table_1[[#This Row],[PAYOUT]]<=60%,"INDEFINIDO","DIVIDENDOS")) | Q27: =VLOOKUP(Table_1[[#This Row],[AÇÕES]],'Dados Status Invest'!A:R,18,0)/100 | R27: =VLOOKUP(Table_1[[#This Row],[AÇÕES]],'Dados Status Invest'!A:Y,25,0)/100 | S27: =(1-Table_1[[#This Row],[PAYOUT]])*Table_1[[#This Row],[ROE]] | T27: =AVERAGE(Table_1[[#This Row],[CAGR LUCRO 5A]],Table_1[[#This Row],[CRESCIMENTO DAMODARAN]]) | U27: =(Table_1[[#This Row],[PREÇO JUSTO BAZIN]]-Table_1[[#This Row],[PREÇO]])/Table_1[[#This Row],[PREÇO JUSTO BAZIN]] | V27: =Table_1[[#This Row],[DPA]]/6% | W27: =Table_1[[#This Row],[PREÇO JUSTO BAZIN]]/(1+Table_1[[#This Row],[MARGEM DE DESCONTO]]) | X27: =(Table_1[[#This Row],[PREÇO JUSTO GRAHAM]]-Table_1[[#This Row],[PREÇO]])/Table_1[[#This Row],[PREÇO JUSTO GRAHAM]] | Y27: =(22.5*Table_1[[#This Row],[LPA]]*Table_1[[#This Row],[VPA]])^0.5 | Z27: =Table_1[[#This Row],[PREÇO JUSTO GRAHAM]]/(1+Table_1[[#This Row],[MARGEM DE DESCONTO]]) | AA27: =(Table_1[[#This Row],[PREÇO JUSTO GORDON]]-Table_1[[#This Row],[PREÇO]])/Table_1[[#This Row],[PREÇO JUSTO GORDON]] | AB27: =Table_1[[#This Row],[DPA]]*(1+Table_1[[#This Row],[MÉDIA DE CRESCIMENTO]]) | AC27: =Table_1[[#This Row],[D1]]/(Table_1[[#This Row],[RISCO]]-Table_1[[#This Row],[MÉDIA DE CRESCIMENTO]]) | AD27: =Table_1[[#This Row],[PREÇO JUSTO GORDON]]/(1+Table_1[[#This Row],[MARGEM DE DESCONTO]]) | AE27: =Table_1[[#This Row],[P/L]]/Table_1[[#This Row],[MÉDIA DE CRESCIMENTO]] | AH27: Entre Zero e 10%
B28: ='Dados Status Invest'!A14 | C28: =VLOOKUP(Table_1[[#This Row],[AÇÕES]],'Classificação B3'!A:B,2,0) | D28: =VLOOKUP(Table_1[[#This Row],[AÇÕES]],'Classificação B3'!A:D,4,0) | E28: =VLOOKUP(Table_1[[#This Row],[AÇÕES]],'Classificação B3'!A:F,6,0) | F28: =VLOOKUP(Table_1[[#This Row],[AÇÕES]],'Classificação B3'!A:G,7,0) | G28: =VLOOKUP(Table_1[[#This Row],[AÇÕES]],'Dados Status Invest'!A:B,2,0) | H28: =VLOOKUP(Table_1[[#This Row],[AÇÕES]],'Dados Status Invest'!A:C,3,0)/100 | I28: =VLOOKUP(Table_1[[#This Row],[AÇÕES]],'Dados Status Invest'!A:D,4,0)/100 | J28: =VLOOKUP(Table_1[[#This Row],[AÇÕES]],'Dados Status Invest'!A:AB,28,0) | K28: =VLOOKUP(Table_1[[#This Row],[AÇÕES]],'Dados Status Invest'!A:AA,27,0) | L28: =Table_1[[#This Row],[PREÇO]]*Table_1[[#This Row],[DY]] | M28: =$E$13 | N28: 0.3 | O28: =Table_1[[#This Row],[DPA]]/Table_1[[#This Row],[LPA]] | P28: =IF(Table_1[[#This Row],[PAYOUT]]<=40%,"CRESCIMENTO",IF(Table_1[[#This Row],[PAYOUT]]<=60%,"INDEFINIDO","DIVIDENDOS")) | Q28: =VLOOKUP(Table_1[[#This Row],[AÇÕES]],'Dados Status Invest'!A:R,18,0)/100 | R28: =VLOOKUP(Table_1[[#This Row],[AÇÕES]],'Dados Status Invest'!A:Y,25,0)/100 | S28: =(1-Table_1[[#This Row],[PAYOUT]])*Table_1[[#This Row],[ROE]] | T28: =AVERAGE(Table_1[[#This Row],[CAGR LUCRO 5A]],Table_1[[#This Row],[CRESCIMENTO DAMODARAN]]) | U28: =(Table_1[[#This Row],[PREÇO JUSTO BAZIN]]-Table_1[[#This Row],[PREÇO]])/Table_1[[#This Row],[PREÇO JUSTO BAZIN]] | V28: =Table_1[[#This Row],[DPA]]/6% | W28: =Table_1[[#This Row],[PREÇO JUSTO BAZIN]]/(1+Table_1[[#This Row],[MARGEM DE DESCONTO]]) | X28: =(Table_1[[#This Row],[PREÇO JUSTO GRAHAM]]-Table_1[[#This Row],[PREÇO]])/Table_1[[#This Row],[PREÇO JUSTO GRAHAM]] | Y28: =(22.5*Table_1[[#This Row],[LPA]]*Table_1[[#This Row],[VPA]])^0.5 | Z28: =Table_1[[#This Row],[PREÇO JUSTO GRAHAM]]/(1+Table_1[[#This Row],[MARGEM DE DESCONTO]]) | AA28: =(Table_1[[#This Row],[PREÇO JUSTO GORDON]]-Table_1[[#This Row],[PREÇO]])/Table_1[[#This Row],[PREÇO JUSTO GORDON]] | AB28: =Table_1[[#This Row],[DPA]]*(1+Table_1[[#This Row],[MÉDIA DE CRESCIMENTO]]) | AC28: =Table_1[[#This Row],[D1]]/(Table_1[[#This Row],[RISCO]]-Table_1[[#This Row],[MÉDIA DE CRESCIMENTO]]) | AD28: =Table_1[[#This Row],[PREÇO JUSTO GORDON]]/(1+Table_1[[#This Row],[MARGEM DE DESCONTO]]) | AE28: =Table_1[[#This Row],[P/L]]/Table_1[[#This Row],[MÉDIA DE CRESCIMENTO]] | AH28: Entre 10% e 20%
B29: ='Dados Status Invest'!A15 | C29: =VLOOKUP(Table_1[[#This Row],[AÇÕES]],'Classificação B3'!A:B,2,0) | D29: =VLOOKUP(Table_1[[#This Row],[AÇÕES]],'Classificação B3'!A:D,4,0) | E29: =VLOOKUP(Table_1[[#This Row],[AÇÕES]],'Classificação B3'!A:F,6,0) | F29: =VLOOKUP(Table_1[[#This Row],[AÇÕES]],'Classificação B3'!A:G,7,0) | G29: =VLOOKUP(Table_1[[#This Row],[AÇÕES]],'Dados Status Invest'!A:B,2,0) | H29: =VLOOKUP(Table_1[[#This Row],[AÇÕES]],'Dados Status Invest'!A:C,3,0)/100 | I29: =VLOOKUP(Table_1[[#This Row],[AÇÕES]],'Dados Status Invest'!A:D,4,0)/100 | J29: =VLOOKUP(Table_1[[#This Row],[AÇÕES]],'Dados Status Invest'!A:AB,28,0) | K29: =VLOOKUP(Table_1[[#This Row],[AÇÕES]],'Dados Status Invest'!A:AA,27,0) | L29: =Table_1[[#This Row],[PREÇO]]*Table_1[[#This Row],[DY]] | M29: =$E$13 | N29: 0.3 | O29: =Table_1[[#This Row],[DPA]]/Table_1[[#This Row],[LPA]] | P29: =IF(Table_1[[#This Row],[PAYOUT]]<=40%,"CRESCIMENTO",IF(Table_1[[#This Row],[PAYOUT]]<=60%,"INDEFINIDO","DIVIDENDOS")) | Q29: =VLOOKUP(Table_1[[#This Row],[AÇÕES]],'Dados Status Invest'!A:R,18,0)/100 | R29: =VLOOKUP(Table_1[[#This Row],[AÇÕES]],'Dados Status Invest'!A:Y,25,0)/100 | S29: =(1-Table_1[[#This Row],[PAYOUT]])*Table_1[[#This Row],[ROE]] | T29: =AVERAGE(Table_1[[#This Row],[CAGR LUCRO 5A]],Table_1[[#This Row],[CRESCIMENTO DAMODARAN]]) | U29: =(Table_1[[#This Row],[PREÇO JUSTO BAZIN]]-Table_1[[#This Row],[PREÇO]])/Table_1[[#This Row],[PREÇO JUSTO BAZIN]] | V29: =Table_1[[#This Row],[DPA]]/6% | W29: =Table_1[[#This Row],[PREÇO JUSTO BAZIN]]/(1+Table_1[[#This Row],[MARGEM DE DESCONTO]]) | X29: =(Table_1[[#This Row],[PREÇO JUSTO GRAHAM]]-Table_1[[#This Row],[PREÇO]])/Table_1[[#This Row],[PREÇO JUSTO GRAHAM]] | Y29: =(22.5*Table_1[[#This Row],[LPA]]*Table_1[[#This Row],[VPA]])^0.5 | Z29: =Table_1[[#This Row],[PREÇO JUSTO GRAHAM]]/(1+Table_1[[#This Row],[MARGEM DE DESCONTO]]) | AA29: =(Table_1[[#This Row],[PREÇO JUSTO GORDON]]-Table_1[[#This Row],[PREÇO]])/Table_1[[#This Row],[PREÇO JUSTO GORDON]] | AB29: =Table_1[[#This Row],[DPA]]*(1+Table_1[[#This Row],[MÉDIA DE CRESCIMENTO]]) | AC29: =Table_1[[#This Row],[D1]]/(Table_1[[#This Row],[RISCO]]-Table_1[[#This Row],[MÉDIA DE CRESCIMENTO]]) | AD29: =Table_1[[#This Row],[PREÇO JUSTO GORDON]]/(1+Table_1[[#This Row],[MARGEM DE DESCONTO]]) | AE29: =Table_1[[#This Row],[P/L]]/Table_1[[#This Row],[MÉDIA DE CRESCIMENTO]] | AH29: Acima de 20%
B30: ='Dados Status Invest'!A16 | C30: =VLOOKUP(Table_1[[#This Row],[AÇÕES]],'Classificação B3'!A:B,2,0) | D30: =VLOOKUP(Table_1[[#This Row],[AÇÕES]],'Classificação B3'!A:D,4,0) | E30: =VLOOKUP(Table_1[[#This Row],[AÇÕES]],'Classificação B3'!A:F,6,0) | F30: =VLOOKUP(Table_1[[#This Row],[AÇÕES]],'Classificação B3'!A:G,7,0) | G30: =VLOOKUP(Table_1[[#This Row],[AÇÕES]],'Dados Status Invest'!A:B,2,0) | H30: =VLOOKUP(Table_1[[#This Row],[AÇÕES]],'Dados Status Invest'!A:C,3,0)/100 | I30: =VLOOKUP(Table_1[[#This Row],[AÇÕES]],'Dados Status Invest'!A:D,4,0)/100 | J30: =VLOOKUP(Table_1[[#This Row],[AÇÕES]],'Dados Status Invest'!A:AB,28,0) | K30: =VLOOKUP(Table_1[[#This Row],[AÇÕES]],'Dados Status Invest'!A:AA,27,0) | L30: =Table_1[[#This Row],[PREÇO]]*Table_1[[#This Row],[DY]] | M30: =$E$13 | N30: 0.3 | O30: =Table_1[[#This Row],[DPA]]/Table_1[[#This Row],[LPA]] | P30: =IF(Table_1[[#This Row],[PAYOUT]]<=40%,"CRESCIMENTO",IF(Table_1[[#This Row],[PAYOUT]]<=60%,"INDEFINIDO","DIVIDENDOS")) | Q30: =VLOOKUP(Table_1[[#This Row],[AÇÕES]],'Dados Status Invest'!A:R,18,0)/100 | R30: =VLOOKUP(Table_1[[#This Row],[AÇÕES]],'Dados Status Invest'!A:Y,25,0)/100 | S30: =(1-Table_1[[#This Row],[PAYOUT]])*Table_1[[#This Row],[ROE]] | T30: =AVERAGE(Table_1[[#This Row],[CAGR LUCRO 5A]],Table_1[[#This Row],[CRESCIMENTO DAMODARAN]]) | U30: =(Table_1[[#This Row],[PREÇO JUSTO BAZIN]]-Table_1[[#This Row],[PREÇO]])/Table_1[[#This Row],[PREÇO JUSTO BAZIN]] | V30: =Table_1[[#This Row],[DPA]]/6% | W30: =Table_1[[#This Row],[PREÇO JUSTO BAZIN]]/(1+Table_1[[#This Row],[MARGEM DE DESCONTO]]) | X30: =(Table_1[[#This Row],[PREÇO JUSTO GRAHAM]]-Table_1[[#This Row],[PREÇO]])/Table_1[[#This Row],[PREÇO JUSTO GRAHAM]] | Y30: =(22.5*Table_1[[#This Row],[LPA]]*Table_1[[#This Row],[VPA]])^0.5 | Z30: =Table_1[[#This Row],[PREÇO JUSTO GRAHAM]]/(1+Table_1[[#This Row],[MARGEM DE DESCONTO]]) | AA30: =(Table_1[[#This Row],[PREÇO JUSTO GORDON]]-Table_1[[#This Row],[PREÇO]])/Table_1[[#This Row],[PREÇO JUSTO GORDON]] | AB30: =Table_1[[#This Row],[DPA]]*(1+Table_1[[#This Row],[MÉDIA DE CRESCIMENTO]]) | AC30: =Table_1[[#This Row],[D1]]/(Table_1[[#This Row],[RISCO]]-Table_1[[#This Row],[MÉDIA DE CRESCIMENTO]]) | AD30: =Table_1[[#This Row],[PREÇO JUSTO GORDON]]/(1+Table_1[[#This Row],[MARGEM DE DESCONTO]]) | AE30: =Table_1[[#This Row],[P/L]]/Table_1[[#This Row],[MÉDIA DE CRESCIMENTO]]
B31: ='Dados Status Invest'!A17 | C31: =VLOOKUP(Table_1[[#This Row],[AÇÕES]],'Classificação B3'!A:B,2,0) | D31: =VLOOKUP(Table_1[[#This Row],[AÇÕES]],'Classificação B3'!A:D,4,0) | E31: =VLOOKUP(Table_1[[#This Row],[AÇÕES]],'Classificação B3'!A:F,6,0) | F31: =VLOOKUP(Table_1[[#This Row],[AÇÕES]],'Classificação B3'!A:G,7,0) | G31: =VLOOKUP(Table_1[[#This Row],[AÇÕES]],'Dados Status Invest'!A:B,2,0) | H31: =VLOOKUP(Table_1[[#This Row],[AÇÕES]],'Dados Status Invest'!A:C,3,0)/100 | I31: =VLOOKUP(Table_1[[#This Row],[AÇÕES]],'Dados Status Invest'!A:D,4,0)/100 | J31: =VLOOKUP(Table_1[[#This Row],[AÇÕES]],'Dados Status Invest'!A:AB,28,0) | K31: =VLOOKUP(Table_1[[#This Row],[AÇÕES]],'Dados Status Invest'!A:AA,27,0) | L31: =Table_1[[#This Row],[PREÇO]]*Table_1[[#This Row],[DY]] | M31: =$E$13 | N31: 0.3 | O31: =Table_1[[#This Row],[DPA]]/Table_1[[#This Row],[LPA]] | P31: =IF(Table_1[[#This Row],[PAYOUT]]<=40%,"CRESCIMENTO",IF(Table_1[[#This Row],[PAYOUT]]<=60%,"INDEFINIDO","DIVIDENDOS")) | Q31: =VLOOKUP(Table_1[[#This Row],[AÇÕES]],'Dados Status Invest'!A:R,18,0)/100 | R31: =VLOOKUP(Table_1[[#This Row],[AÇÕES]],'Dados Status Invest'!A:Y,25,0)/100 | S31: =(1-Table_1[[#This Row],[PAYOUT]])*Table_1[[#This Row],[ROE]] | T31: =AVERAGE(Table_1[[#This Row],[CAGR LUCRO 5A]],Table_1[[#This Row],[CRESCIMENTO DAMODARAN]]) | U31: =(Table_1[[#This Row],[PREÇO JUSTO BAZIN]]-Table_1[[#This Row],[PREÇO]])/Table_1[[#This Row],[PREÇO JUSTO BAZIN]] | V31: =Table_1[[#This Row],[DPA]]/6% | W31: =Table_1[[#This Row],[PREÇO JUSTO BAZIN]]/(1+Table_1[[#This Row],[MARGEM DE DESCONTO]]) | X31: =(Table_1[[#This Row],[PREÇO JUSTO GRAHAM]]-Table_1[[#This Row],[PREÇO]])/Table_1[[#This Row],[PREÇO JUSTO GRAHAM]] | Y31: =(22.5*Table_1[[#This Row],[LPA]]*Table_1[[#This Row],[VPA]])^0.5 | Z31: =Table_1[[#This Row],[PREÇO JUSTO GRAHAM]]/(1+Table_1[[#This Row],[MARGEM DE DESCONTO]]) | AA31: =(Table_1[[#This Row],[PREÇO JUSTO GORDON]]-Table_1[[#This Row],[PREÇO]])/Table_1[[#This Row],[PREÇO JUSTO GORDON]] | AB31: =Table_1[[#This Row],[DPA]]*(1+Table_1[[#This Row],[MÉDIA DE CRESCIMENTO]]) | AC31: =Table_1[[#This Row],[D1]]/(Table_1[[#This Row],[RISCO]]-Table_1[[#This Row],[MÉDIA DE CRESCIMENTO]]) | AD31: =Table_1[[#This Row],[PREÇO JUSTO GORDON]]/(1+Table_1[[#This Row],[MARGEM DE DESCONTO]]) | AE31: =Table_1[[#This Row],[P/L]]/Table_1[[#This Row],[MÉDIA DE CRESCIMENTO]] | AG31: CRESCIMENTO X DIVIDENDOS
B32: ='Dados Status Invest'!A18 | C32: =VLOOKUP(Table_1[[#This Row],[AÇÕES]],'Classificação B3'!A:B,2,0) | D32: =VLOOKUP(Table_1[[#This Row],[AÇÕES]],'Classificação B3'!A:D,4,0) | E32: =VLOOKUP(Table_1[[#This Row],[AÇÕES]],'Classificação B3'!A:F,6,0) | F32: =VLOOKUP(Table_1[[#This Row],[AÇÕES]],'Classificação B3'!A:G,7,0) | G32: =VLOOKUP(Table_1[[#This Row],[AÇÕES]],'Dados Status Invest'!A:B,2,0) | H32: =VLOOKUP(Table_1[[#This Row],[AÇÕES]],'Dados Status Invest'!A:C,3,0)/100 | I32: =VLOOKUP(Table_1[[#This Row],[AÇÕES]],'Dados Status Invest'!A:D,4,0)/100 | J32: =VLOOKUP(Table_1[[#This Row],[AÇÕES]],'Dados Status Invest'!A:AB,28,0) | K32: =VLOOKUP(Table_1[[#This Row],[AÇÕES]],'Dados Status Invest'!A:AA,27,0) | L32: =Table_1[[#This Row],[PREÇO]]*Table_1[[#This Row],[DY]] | M32: =$E$13 | N32: 0.3 | O32: =Table_1[[#This Row],[DPA]]/Table_1[[#This Row],[LPA]] | P32: =IF(Table_1[[#This Row],[PAYOUT]]<=40%,"CRESCIMENTO",IF(Table_1[[#This Row],[PAYOUT]]<=60%,"INDEFINIDO","DIVIDENDOS")) | Q32: =VLOOKUP(Table_1[[#This Row],[AÇÕES]],'Dados Status Invest'!A:R,18,0)/100 | R32: =VLOOKUP(Table_1[[#This Row],[AÇÕES]],'Dados Status Invest'!A:Y,25,0)/100 | S32: =(1-Table_1[[#This Row],[PAYOUT]])*Table_1[[#This Row],[ROE]] | T32: =AVERAGE(Table_1[[#This Row],[CAGR LUCRO 5A]],Table_1[[#This Row],[CRESCIMENTO DAMODARAN]]) | U32: =(Table_1[[#This Row],[PREÇO JUSTO BAZIN]]-Table_1[[#This Row],[PREÇO]])/Table_1[[#This Row],[PREÇO JUSTO BAZIN]] | V32: =Table_1[[#This Row],[DPA]]/6% | W32: =Table_1[[#This Row],[PREÇO JUSTO BAZIN]]/(1+Table_1[[#This Row],[MARGEM DE DESCONTO]]) | X32: =(Table_1[[#This Row],[PREÇO JUSTO GRAHAM]]-Table_1[[#This Row],[PREÇO]])/Table_1[[#This Row],[PREÇO JUSTO GRAHAM]] | Y32: =(22.5*Table_1[[#This Row],[LPA]]*Table_1[[#This Row],[VPA]])^0.5 | Z32: =Table_1[[#This Row],[PREÇO JUSTO GRAHAM]]/(1+Table_1[[#This Row],[MARGEM DE DESCONTO]]) | AA32: =(Table_1[[#This Row],[PREÇO JUSTO GORDON]]-Table_1[[#This Row],[PREÇO]])/Table_1[[#This Row],[PREÇO JUSTO GORDON]] | AB32: =Table_1[[#This Row],[DPA]]*(1+Table_1[[#This Row],[MÉDIA DE CRESCIMENTO]]) | AC32: =Table_1[[#This Row],[D1]]/(Table_1[[#This Row],[RISCO]]-Table_1[[#This Row],[MÉDIA DE CRESCIMENTO]]) | AD32: =Table_1[[#This Row],[PREÇO JUSTO GORDON]]/(1+Table_1[[#This Row],[MARGEM DE DESCONTO]]) | AE32: =Table_1[[#This Row],[P/L]]/Table_1[[#This Row],[MÉDIA DE CRESCIMENTO]] | AG32: DIVIDENDOS | AH32: PAYOUT MAIOR OU IGUAL A 60%
B33: ='Dados Status Invest'!A19 | C33: =VLOOKUP(Table_1[[#This Row],[AÇÕES]],'Classificação B3'!A:B,2,0) | D33: =VLOOKUP(Table_1[[#This Row],[AÇÕES]],'Classificação B3'!A:D,4,0) | E33: =VLOOKUP(Table_1[[#This Row],[AÇÕES]],'Classificação B3'!A:F,6,0) | F33: =VLOOKUP(Table_1[[#This Row],[AÇÕES]],'Classificação B3'!A:G,7,0) | G33: =VLOOKUP(Table_1[[#This Row],[AÇÕES]],'Dados Status Invest'!A:B,2,0) | H33: =VLOOKUP(Table_1[[#This Row],[AÇÕES]],'Dados Status Invest'!A:C,3,0)/100 | I33: =VLOOKUP(Table_1[[#This Row],[AÇÕES]],'Dados Status Invest'!A:D,4,0)/100 | J33: =VLOOKUP(Table_1[[#This Row],[AÇÕES]],'Dados Status Invest'!A:AB,28,0) | K33: =VLOOKUP(Table_1[[#This Row],[AÇÕES]],'Dados Status Invest'!A:AA,27,0) | L33: =Table_1[[#This Row],[PREÇO]]*Table_1[[#This Row],[DY]] | M33: =$E$13 | N33: 0.3 | O33: =Table_1[[#This Row],[DPA]]/Table_1[[#This Row],[LPA]] | P33: =IF(Table_1[[#This Row],[PAYOUT]]<=40%,"CRESCIMENTO",IF(Table_1[[#This Row],[PAYOUT]]<=60%,"INDEFINIDO","DIVIDENDOS")) | Q33: =VLOOKUP(Table_1[[#This Row],[AÇÕES]],'Dados Status Invest'!A:R,18,0)/100 | R33: =VLOOKUP(Table_1[[#This Row],[AÇÕES]],'Dados Status Invest'!A:Y,25,0)/100 | S33: =(1-Table_1[[#This Row],[PAYOUT]])*Table_1[[#This Row],[ROE]] | T33: =AVERAGE(Table_1[[#This Row],[CAGR LUCRO 5A]],Table_1[[#This Row],[CRESCIMENTO DAMODARAN]]) | U33: =(Table_1[[#This Row],[PREÇO JUSTO BAZIN]]-Table_1[[#This Row],[PREÇO]])/Table_1[[#This Row],[PREÇO JUSTO BAZIN]] | V33: =Table_1[[#This Row],[DPA]]/6% | W33: =Table_1[[#This Row],[PREÇO JUSTO BAZIN]]/(1+Table_1[[#This Row],[MARGEM DE DESCONTO]]) | X33: =(Table_1[[#This Row],[PREÇO JUSTO GRAHAM]]-Table_1[[#This Row],[PREÇO]])/Table_1[[#This Row],[PREÇO JUSTO GRAHAM]] | Y33: =(22.5*Table_1[[#This Row],[LPA]]*Table_1[[#This Row],[VPA]])^0.5 | Z33: =Table_1[[#This Row],[PREÇO JUSTO GRAHAM]]/(1+Table_1[[#This Row],[MARGEM DE DESCONTO]]) | AA33: =(Table_1[[#This Row],[PREÇO JUSTO GORDON]]-Table_1[[#This Row],[PREÇO]])/Table_1[[#This Row],[PREÇO JUSTO GORDON]] | AB33: =Table_1[[#This Row],[DPA]]*(1+Table_1[[#This Row],[MÉDIA DE CRESCIMENTO]]) | AC33: =Table_1[[#This Row],[D1]]/(Table_1[[#This Row],[RISCO]]-Table_1[[#This Row],[MÉDIA DE CRESCIMENTO]]) | AD33: =Table_1[[#This Row],[PREÇO JUSTO GORDON]]/(1+Table_1[[#This Row],[MARGEM DE DESCONTO]]) | AE33: =Table_1[[#This Row],[P/L]]/Table_1[[#This Row],[MÉDIA DE CRESCIMENTO]] | AG33: CRESCIMENTO | AH33: PAYOUT MENOR OU IGUAL A 40%
B34: ='Dados Status Invest'!A20 | C34: =VLOOKUP(Table_1[[#This Row],[AÇÕES]],'Classificação B3'!A:B,2,0) | D34: =VLOOKUP(Table_1[[#This Row],[AÇÕES]],'Classificação B3'!A:D,4,0) | E34: =VLOOKUP(Table_1[[#This Row],[AÇÕES]],'Classificação B3'!A:F,6,0) | F34: =VLOOKUP(Table_1[[#This Row],[AÇÕES]],'Classificação B3'!A:G,7,0) | G34: =VLOOKUP(Table_1[[#This Row],[AÇÕES]],'Dados Status Invest'!A:B,2,0) | H34: =VLOOKUP(Table_1[[#This Row],[AÇÕES]],'Dados Status Invest'!A:C,3,0)/100 | I34: =VLOOKUP(Table_1[[#This Row],[AÇÕES]],'Dados Status Invest'!A:D,4,0)/100 | J34: =VLOOKUP(Table_1[[#This Row],[AÇÕES]],'Dados Status Invest'!A:AB,28,0) | K34: =VLOOKUP(Table_1[[#This Row],[AÇÕES]],'Dados Status Invest'!A:AA,27,0) | L34: =Table_1[[#This Row],[PREÇO]]*Table_1[[#This Row],[DY]] | M34: =$E$13 | N34: 0.3 | O34: =Table_1[[#This Row],[DPA]]/Table_1[[#This Row],[LPA]] | P34: =IF(Table_1[[#This Row],[PAYOUT]]<=40%,"CRESCIMENTO",IF(Table_1[[#This Row],[PAYOUT]]<=60%,"INDEFINIDO","DIVIDENDOS")) | Q34: =VLOOKUP(Table_1[[#This Row],[AÇÕES]],'Dados Status Invest'!A:R,18,0)/100 | R34: =VLOOKUP(Table_1[[#This Row],[AÇÕES]],'Dados Status Invest'!A:Y,25,0)/100 | S34: =(1-Table_1[[#This Row],[PAYOUT]])*Table_1[[#This Row],[ROE]] | T34: =AVERAGE(Table_1[[#This Row],[CAGR LUCRO 5A]],Table_1[[#This Row],[CRESCIMENTO DAMODARAN]]) | U34: =(Table_1[[#This Row],[PREÇO JUSTO BAZIN]]-Table_1[[#This Row],[PREÇO]])/Table_1[[#This Row],[PREÇO JUSTO BAZIN]] | V34: =Table_1[[#This Row],[DPA]]/6% | W34: =Table_1[[#This Row],[PREÇO JUSTO BAZIN]]/(1+Table_1[[#This Row],[MARGEM DE DESCONTO]]) | X34: =(Table_1[[#This Row],[PREÇO JUSTO GRAHAM]]-Table_1[[#This Row],[PREÇO]])/Table_1[[#This Row],[PREÇO JUSTO GRAHAM]] | Y34: =(22.5*Table_1[[#This Row],[LPA]]*Table_1[[#This Row],[VPA]])^0.5 | Z34: =Table_1[[#This Row],[PREÇO JUSTO GRAHAM]]/(1+Table_1[[#This Row],[MARGEM DE DESCONTO]]) | AA34: =(Table_1[[#This Row],[PREÇO JUSTO GORDON]]-Table_1[[#This Row],[PREÇO]])/Table_1[[#This Row],[PREÇO JUSTO GORDON]] | AB34: =Table_1[[#This Row],[DPA]]*(1+Table_1[[#This Row],[MÉDIA DE CRESCIMENTO]]) | AC34: =Table_1[[#This Row],[D1]]/(Table_1[[#This Row],[RISCO]]-Table_1[[#This Row],[MÉDIA DE CRESCIMENTO]]) | AD34: =Table_1[[#This Row],[PREÇO JUSTO GORDON]]/(1+Table_1[[#This Row],[MARGEM DE DESCONTO]]) | AE34: =Table_1[[#This Row],[P/L]]/Table_1[[#This Row],[MÉDIA DE CRESCIMENTO]] | AG34: INDEFINIDO | AH34: PAYOUT ENTRE 40 E 60%
B35: ='Dados Status Invest'!A21 | C35: =VLOOKUP(Table_1[[#This Row],[AÇÕES]],'Classificação B3'!A:B,2,0) | D35: =VLOOKUP(Table_1[[#This Row],[AÇÕES]],'Classificação B3'!A:D,4,0) | E35: =VLOOKUP(Table_1[[#This Row],[AÇÕES]],'Classificação B3'!A:F,6,0) | F35: =VLOOKUP(Table_1[[#This Row],[AÇÕES]],'Classificação B3'!A:G,7,0) | G35: =VLOOKUP(Table_1[[#This Row],[AÇÕES]],'Dados Status Invest'!A:B,2,0) | H35: =VLOOKUP(Table_1[[#This Row],[AÇÕES]],'Dados Status Invest'!A:C,3,0)/100 | I35: =VLOOKUP(Table_1[[#This Row],[AÇÕES]],'Dados Status Invest'!A:D,4,0)/100 | J35: =VLOOKUP(Table_1[[#This Row],[AÇÕES]],'Dados Status Invest'!A:AB,28,0) | K35: =VLOOKUP(Table_1[[#This Row],[AÇÕES]],'Dados Status Invest'!A:AA,27,0) | L35: =Table_1[[#This Row],[PREÇO]]*Table_1[[#This Row],[DY]] | M35: =$E$13 | N35: 0.3 | O35: =Table_1[[#This Row],[DPA]]/Table_1[[#This Row],[LPA]] | P35: =IF(Table_1[[#This Row],[PAYOUT]]<=40%,"CRESCIMENTO",IF(Table_1[[#This Row],[PAYOUT]]<=60%,"INDEFINIDO","DIVIDENDOS")) | Q35: =VLOOKUP(Table_1[[#This Row],[AÇÕES]],'Dados Status Invest'!A:R,18,0)/100 | R35: =VLOOKUP(Table_1[[#This Row],[AÇÕES]],'Dados Status Invest'!A:Y,25,0)/100 | S35: =(1-Table_1[[#This Row],[PAYOUT]])*Table_1[[#This Row],[ROE]] | T35: =AVERAGE(Table_1[[#This Row],[CAGR LUCRO 5A]],Table_1[[#This Row],[CRESCIMENTO DAMODARAN]]) | U35: =(Table_1[[#This Row],[PREÇO JUSTO BAZIN]]-Table_1[[#This Row],[PREÇO]])/Table_1[[#This Row],[PREÇO JUSTO BAZIN]] | V35: =Table_1[[#This Row],[DPA]]/6% | W35: =Table_1[[#This Row],[PREÇO JUSTO BAZIN]]/(1+Table_1[[#This Row],[MARGEM DE DESCONTO]]) | X35: =(Table_1[[#This Row],[PREÇO JUSTO GRAHAM]]-Table_1[[#This Row],[PREÇO]])/Table_1[[#This Row],[PREÇO JUSTO GRAHAM]] | Y35: =(22.5*Table_1[[#This Row],[LPA]]*Table_1[[#This Row],[VPA]])^0.5 | Z35: =Table_1[[#This Row],[PREÇO JUSTO GRAHAM]]/(1+Table_1[[#This Row],[MARGEM DE DESCONTO]]) | AA35: =(Table_1[[#This Row],[PREÇO JUSTO GORDON]]-Table_1[[#This Row],[PREÇO]])/Table_1[[#This Row],[PREÇO JUSTO GORDON]] | AB35: =Table_1[[#This Row],[DPA]]*(1+Table_1[[#This Row],[MÉDIA DE CRESCIMENTO]]) | AC35: =Table_1[[#This Row],[D1]]/(Table_1[[#This Row],[RISCO]]-Table_1[[#This Row],[MÉDIA DE CRESCIMENTO]]) | AD35: =Table_1[[#This Row],[PREÇO JUSTO GORDON]]/(1+Table_1[[#This Row],[MARGEM DE DESCONTO]]) | AE35: =Table_1[[#This Row],[P/L]]/Table_1[[#This Row],[MÉDIA DE CRESCIMENTO]]
B36: ='Dados Status Invest'!A22 | C36: =VLOOKUP(Table_1[[#This Row],[AÇÕES]],'Classificação B3'!A:B,2,0) | D36: =VLOOKUP(Table_1[[#This Row],[AÇÕES]],'Classificação B3'!A:D,4,0) | E36: =VLOOKUP(Table_1[[#This Row],[AÇÕES]],'Classificação B3'!A:F,6,0) | F36: =VLOOKUP(Table_1[[#This Row],[AÇÕES]],'Classificação B3'!A:G,7,0) | G36: =VLOOKUP(Table_1[[#This Row],[AÇÕES]],'Dados Status Invest'!A:B,2,0) | H36: =VLOOKUP(Table_1[[#This Row],[AÇÕES]],'Dados Status Invest'!A:C,3,0)/100 | I36: =VLOOKUP(Table_1[[#This Row],[AÇÕES]],'Dados Status Invest'!A:D,4,0)/100 | J36: =VLOOKUP(Table_1[[#This Row],[AÇÕES]],'Dados Status Invest'!A:AB,28,0) | K36: =VLOOKUP(Table_1[[#This Row],[AÇÕES]],'Dados Status Invest'!A:AA,27,0) | L36: =Table_1[[#This Row],[PREÇO]]*Table_1[[#This Row],[DY]] | M36: =$E$13 | N36: 0.3 | O36: =Table_1[[#This Row],[DPA]]/Table_1[[#This Row],[LPA]] | P36: =IF(Table_1[[#This Row],[PAYOUT]]<=40%,"CRESCIMENTO",IF(Table_1[[#This Row],[PAYOUT]]<=60%,"INDEFINIDO","DIVIDENDOS")) | Q36: =VLOOKUP(Table_1[[#This Row],[AÇÕES]],'Dados Status Invest'!A:R,18,0)/100 | R36: =VLOOKUP(Table_1[[#This Row],[AÇÕES]],'Dados Status Invest'!A:Y,25,0)/100 | S36: =(1-Table_1[[#This Row],[PAYOUT]])*Table_1[[#This Row],[ROE]] | T36: =AVERAGE(Table_1[[#This Row],[CAGR LUCRO 5A]],Table_1[[#This Row],[CRESCIMENTO DAMODARAN]]) | U36: =(Table_1[[#This Row],[PREÇO JUSTO BAZIN]]-Table_1[[#This Row],[PREÇO]])/Table_1[[#This Row],[PREÇO JUSTO BAZIN]] | V36: =Table_1[[#This Row],[DPA]]/6% | W36: =Table_1[[#This Row],[PREÇO JUSTO BAZIN]]/(1+Table_1[[#This Row],[MARGEM DE DESCONTO]]) | X36: =(Table_1[[#This Row],[PREÇO JUSTO GRAHAM]]-Table_1[[#This Row],[PREÇO]])/Table_1[[#This Row],[PREÇO JUSTO GRAHAM]] | Y36: =(22.5*Table_1[[#This Row],[LPA]]*Table_1[[#This Row],[VPA]])^0.5 | Z36: =Table_1[[#This Row],[PREÇO JUSTO GRAHAM]]/(1+Table_1[[#This Row],[MARGEM DE DESCONTO]]) | AA36: =(Table_1[[#This Row],[PREÇO JUSTO GORDON]]-Table_1[[#This Row],[PREÇO]])/Table_1[[#This Row],[PREÇO JUSTO GORDON]] | AB36: =Table_1[[#This Row],[DPA]]*(1+Table_1[[#This Row],[MÉDIA DE CRESCIMENTO]]) | AC36: =Table_1[[#This Row],[D1]]/(Table_1[[#This Row],[RISCO]]-Table_1[[#This Row],[MÉDIA DE CRESCIMENTO]]) | AD36: =Table_1[[#This Row],[PREÇO JUSTO GORDON]]/(1+Table_1[[#This Row],[MARGEM DE DESCONTO]]) | AE36: =Table_1[[#This Row],[P/L]]/Table_1[[#This Row],[MÉDIA DE CRESCIMENTO]]
B37: ='Dados Status Invest'!A23 | C37: =VLOOKUP(Table_1[[#This Row],[AÇÕES]],'Classificação B3'!A:B,2,0) | D37: =VLOOKUP(Table_1[[#This Row],[AÇÕES]],'Classificação B3'!A:D,4,0) | E37: =VLOOKUP(Table_1[[#This Row],[AÇÕES]],'Classificação B3'!A:F,6,0) | F37: =VLOOKUP(Table_1[[#This Row],[AÇÕES]],'Classificação B3'!A:G,7,0) | G37: =VLOOKUP(Table_1[[#This Row],[AÇÕES]],'Dados Status Invest'!A:B,2,0) | H37: =VLOOKUP(Table_1[[#This Row],[AÇÕES]],'Dados Status Invest'!A:C,3,0)/100 | I37: =VLOOKUP(Table_1[[#This Row],[AÇÕES]],'Dados Status Invest'!A:D,4,0)/100 | J37: =VLOOKUP(Table_1[[#This Row],[AÇÕES]],'Dados Status Invest'!A:AB,28,0) | K37: =VLOOKUP(Table_1[[#This Row],[AÇÕES]],'Dados Status Invest'!A:AA,27,0) | L37: =Table_1[[#This Row],[PREÇO]]*Table_1[[#This Row],[DY]] | M37: =$E$13 | N37: 0.3 | O37: =Table_1[[#This Row],[DPA]]/Table_1[[#This Row],[LPA]] | P37: =IF(Table_1[[#This Row],[PAYOUT]]<=40%,"CRESCIMENTO",IF(Table_1[[#This Row],[PAYOUT]]<=60%,"INDEFINIDO","DIVIDENDOS")) | Q37: =VLOOKUP(Table_1[[#This Row],[AÇÕES]],'Dados Status Invest'!A:R,18,0)/100 | R37: =VLOOKUP(Table_1[[#This Row],[AÇÕES]],'Dados Status Invest'!A:Y,25,0)/100 | S37: =(1-Table_1[[#This Row],[PAYOUT]])*Table_1[[#This Row],[ROE]] | T37: =AVERAGE(Table_1[[#This Row],[CAGR LUCRO 5A]],Table_1[[#This Row],[CRESCIMENTO DAMODARAN]]) | U37: =(Table_1[[#This Row],[PREÇO JUSTO BAZIN]]-Table_1[[#This Row],[PREÇO]])/Table_1[[#This Row],[PREÇO JUSTO BAZIN]] | V37: =Table_1[[#This Row],[DPA]]/6% | W37: =Table_1[[#This Row],[PREÇO JUSTO BAZIN]]/(1+Table_1[[#This Row],[MARGEM DE DESCONTO]]) | X37: =(Table_1[[#This Row],[PREÇO JUSTO GRAHAM]]-Table_1[[#This Row],[PREÇO]])/Table_1[[#This Row],[PREÇO JUSTO GRAHAM]] | Y37: =(22.5*Table_1[[#This Row],[LPA]]*Table_1[[#This Row],[VPA]])^0.5 | Z37: =Table_1[[#This Row],[PREÇO JUSTO GRAHAM]]/(1+Table_1[[#This Row],[MARGEM DE DESCONTO]]) | AA37: =(Table_1[[#This Row],[PREÇO JUSTO GORDON]]-Table_1[[#This Row],[PREÇO]])/Table_1[[#This Row],[PREÇO JUSTO GORDON]] | AB37: =Table_1[[#This Row],[DPA]]*(1+Table_1[[#This Row],[MÉDIA DE CRESCIMENTO]]) | AC37: =Table_1[[#This Row],[D1]]/(Table_1[[#This Row],[RISCO]]-Table_1[[#This Row],[MÉDIA DE CRESCIMENTO]]) | AD37: =Table_1[[#This Row],[PREÇO JUSTO GORDON]]/(1+Table_1[[#This Row],[MARGEM DE DESCONTO]]) | AE37: =Table_1[[#This Row],[P/L]]/Table_1[[#This Row],[MÉDIA DE CRESCIMENTO]]
B38: ='Dados Status Invest'!A24 | C38: =VLOOKUP(Table_1[[#This Row],[AÇÕES]],'Classificação B3'!A:B,2,0) | D38: =VLOOKUP(Table_1[[#This Row],[AÇÕES]],'Classificação B3'!A:D,4,0) | E38: =VLOOKUP(Table_1[[#This Row],[AÇÕES]],'Classificação B3'!A:F,6,0) | F38: =VLOOKUP(Table_1[[#This Row],[AÇÕES]],'Classificação B3'!A:G,7,0) | G38: =VLOOKUP(Table_1[[#This Row],[AÇÕES]],'Dados Status Invest'!A:B,2,0) | H38: =VLOOKUP(Table_1[[#This Row],[AÇÕES]],'Dados Status Invest'!A:C,3,0)/100 | I38: =VLOOKUP(Table_1[[#This Row],[AÇÕES]],'Dados Status Invest'!A:D,4,0)/100 | J38: =VLOOKUP(Table_1[[#This Row],[AÇÕES]],'Dados Status Invest'!A:AB,28,0) | K38: =VLOOKUP(Table_1[[#This Row],[AÇÕES]],'Dados Status Invest'!A:AA,27,0) | L38: =Table_1[[#This Row],[PREÇO]]*Table_1[[#This Row],[DY]] | M38: =$E$13 | N38: 0.3 | O38: =Table_1[[#This Row],[DPA]]/Table_1[[#This Row],[LPA]] | P38: =IF(Table_1[[#This Row],[PAYOUT]]<=40%,"CRESCIMENTO",IF(Table_1[[#This Row],[PAYOUT]]<=60%,"INDEFINIDO","DIVIDENDOS")) | Q38: =VLOOKUP(Table_1[[#This Row],[AÇÕES]],'Dados Status Invest'!A:R,18,0)/100 | R38: =VLOOKUP(Table_1[[#This Row],[AÇÕES]],'Dados Status Invest'!A:Y,25,0)/100 | S38: =(1-Table_1[[#This Row],[PAYOUT]])*Table_1[[#This Row],[ROE]] | T38: =AVERAGE(Table_1[[#This Row],[CAGR LUCRO 5A]],Table_1[[#This Row],[CRESCIMENTO DAMODARAN]]) | U38: =(Table_1[[#This Row],[PREÇO JUSTO BAZIN]]-Table_1[[#This Row],[PREÇO]])/Table_1[[#This Row],[PREÇO JUSTO BAZIN]] | V38: =Table_1[[#This Row],[DPA]]/6% | W38: =Table_1[[#This Row],[PREÇO JUSTO BAZIN]]/(1+Table_1[[#This Row],[MARGEM DE DESCONTO]]) | X38: =(Table_1[[#This Row],[PREÇO JUSTO GRAHAM]]-Table_1[[#This Row],[PREÇO]])/Table_1[[#This Row],[PREÇO JUSTO GRAHAM]] | Y38: =(22.5*Table_1[[#This Row],[LPA]]*Table_1[[#This Row],[VPA]])^0.5 | Z38: =Table_1[[#This Row],[PREÇO JUSTO GRAHAM]]/(1+Table_1[[#This Row],[MARGEM DE DESCONTO]]) | AA38: =(Table_1[[#This Row],[PREÇO JUSTO GORDON]]-Table_1[[#This Row],[PREÇO]])/Table_1[[#This Row],[PREÇO JUSTO GORDON]] | AB38: =Table_1[[#This Row],[DPA]]*(1+Table_1[[#This Row],[MÉDIA DE CRESCIMENTO]]) | AC38: =Table_1[[#This Row],[D1]]/(Table_1[[#This Row],[RISCO]]-Table_1[[#This Row],[MÉDIA DE CRESCIMENTO]]) | AD38: =Table_1[[#This Row],[PREÇO JUSTO GORDON]]/(1+Table_1[[#This Row],[MARGEM DE DESCONTO]]) | AE38: =Table_1[[#This Row],[P/L]]/Table_1[[#This Row],[MÉDIA DE CRESCIMENTO]]
B39: ='Dados Status Invest'!A25 | C39: =VLOOKUP(Table_1[[#This Row],[AÇÕES]],'Classificação B3'!A:B,2,0) | D39: =VLOOKUP(Table_1[[#This Row],[AÇÕES]],'Classificação B3'!A:D,4,0) | E39: =VLOOKUP(Table_1[[#This Row],[AÇÕES]],'Classificação B3'!A:F,6,0) | F39: =VLOOKUP(Table_1[[#This Row],[AÇÕES]],'Classificação B3'!A:G,7,0) | G39: =VLOOKUP(Table_1[[#This Row],[AÇÕES]],'Dados Status Invest'!A:B,2,0) | H39: =VLOOKUP(Table_1[[#This Row],[AÇÕES]],'Dados Status Invest'!A:C,3,0)/100 | I39: =VLOOKUP(Table_1[[#This Row],[AÇÕES]],'Dados Status Invest'!A:D,4,0)/100 | J39: =VLOOKUP(Table_1[[#This Row],[AÇÕES]],'Dados Status Invest'!A:AB,28,0) | K39: =VLOOKUP(Table_1[[#This Row],[AÇÕES]],'Dados Status Invest'!A:AA,27,0) | L39: =Table_1[[#This Row],[PREÇO]]*Table_1[[#This Row],[DY]] | M39: =$E$13 | N39: 0.3 | O39: =Table_1[[#This Row],[DPA]]/Table_1[[#This Row],[LPA]] | P39: =IF(Table_1[[#This Row],[PAYOUT]]<=40%,"CRESCIMENTO",IF(Table_1[[#This Row],[PAYOUT]]<=60%,"INDEFINIDO","DIVIDENDOS")) | Q39: =VLOOKUP(Table_1[[#This Row],[AÇÕES]],'Dados Status Invest'!A:R,18,0)/100 | R39: =VLOOKUP(Table_1[[#This Row],[AÇÕES]],'Dados Status Invest'!A:Y,25,0)/100 | S39: =(1-Table_1[[#This Row],[PAYOUT]])*Table_1[[#This Row],[ROE]] | T39: =AVERAGE(Table_1[[#This Row],[CAGR LUCRO 5A]],Table_1[[#This Row],[CRESCIMENTO DAMODARAN]]) | U39: =(Table_1[[#This Row],[PREÇO JUSTO BAZIN]]-Table_1[[#This Row],[PREÇO]])/Table_1[[#This Row],[PREÇO JUSTO BAZIN]] | V39: =Table_1[[#This Row],[DPA]]/6% | W39: =Table_1[[#This Row],[PREÇO JUSTO BAZIN]]/(1+Table_1[[#This Row],[MARGEM DE DESCONTO]]) | X39: =(Table_1[[#This Row],[PREÇO JUSTO GRAHAM]]-Table_1[[#This Row],[PREÇO]])/Table_1[[#This Row],[PREÇO JUSTO GRAHAM]] | Y39: =(22.5*Table_1[[#This Row],[LPA]]*Table_1[[#This Row],[VPA]])^0.5 | Z39: =Table_1[[#This Row],[PREÇO JUSTO GRAHAM]]/(1+Table_1[[#This Row],[MARGEM DE DESCONTO]]) | AA39: =(Table_1[[#This Row],[PREÇO JUSTO GORDON]]-Table_1[[#This Row],[PREÇO]])/Table_1[[#This Row],[PREÇO JUSTO GORDON]] | AB39: =Table_1[[#This Row],[DPA]]*(1+Table_1[[#This Row],[MÉDIA DE CRESCIMENTO]]) | AC39: =Table_1[[#This Row],[D1]]/(Table_1[[#This Row],[RISCO]]-Table_1[[#This Row],[MÉDIA DE CRESCIMENTO]]) | AD39: =Table_1[[#This Row],[PREÇO JUSTO GORDON]]/(1+Table_1[[#This Row],[MARGEM DE DESCONTO]]) | AE39: =Table_1[[#This Row],[P/L]]/Table_1[[#This Row],[MÉDIA DE CRESCIMENTO]]
